Workbook
Name курс: 'Исходные данные'!$H$27:$V$27
Name период: 'Исходные данные'!$H$2:$V$2
Name период_знач: 'Исходные данные'!$H$3:$V$3
Name период_календ: 'Исходные данные'!$H$3:$R$3

Sheet Исходные данные
B1: Параметры модели
D2: Номер периода | H2: 1 | I2: 2 | J2: 3 | K2: 4 | L2: 5 | M2: 6 | N2: 7 | O2: 8 | P2: 9 | Q2: 10 | R2: 11 | S2: 12 | T2: 13 | U2: 14 | V2: 15
D3: Календарный год | H3: 2020 | I3: 2021 | J3: 2022 | K3: 2023 | L3: 2024 | M3: 2025 | N3: 2026 | O3: 2027 | P3: 2028 | Q3: 2029 | R3: 2030 | S3: 2031 | T3: 2032 | U3: 2033 | V3: 2034
A5: 1 | B5: Допущения и константы
D7: Тройская унция в граммах | E7: грамм/Oz | H7: 31.103477
D8: Ставка дисконтирования | E8: % | H8: 0.15
D9: Сценарий | H9: Собственная электростанция | L9: =IF(H9="Покупная электроэнергия",1,2) -> 2
A11: 2 | B11: Прогнозы налогов, сборов и отчислений
D13: Налог на добавленную стоимость (НДС), в том числе: | E13: %
D14: по ставке | E14: % | H14: 0.2 | I14: 0.2 | J14: 0.2 | K14: 0.2 | L14: 0.2 | M14: 0.2 | N14: 0.2 | O14: 0.2 | P14: 0.2 | Q14: 0.2 | R14: 0.2 | S14: 0.2 | T14: 0.2 | U14: 0.2 | V14: 0.2
D15: по ставке | E15: % | H15: 0.1 | I15: 0.1 | J15: 0.1 | K15: 0.1 | L15: 0.1 | M15: 0.1 | N15: 0.1 | O15: 0.1 | P15: 0.1 | Q15: 0.1 | R15: 0.1 | S15: 0.1 | T15: 0.1 | U15: 0.1 | V15: 0.1
D16: по ставке | E16: % | H16: 0 | I16: 0 | J16: 0 | K16: 0 | L16: 0 | M16: 0 | N16: 0 | O16: 0 | P16: 0 | Q16: 0 | R16: 0 | S16: 0 | T16: 0 | U16: 0 | V16: 0
D17: Налог на добычу полезных ископаемых (НДПИ), в т. ч.: | E17: %
D18: по ставке (золото) | E18: % | H18: 0.06 | I18: 0.06 | J18: 0.06 | K18: 0.06 | L18: 0.06 | M18: 0.06 | N18: 0.06 | O18: 0.06 | P18: 0.06 | Q18: 0.06 | R18: 0.06 | S18: 0.06 | T18: 0.06 | U18: 0.06 | V18: 0.06
D19: по ставке (серебро) | E19: % | H19: 0.065 | I19: 0.065 | J19: 0.065 | K19: 0.065 | L19: 0.065 | M19: 0.065 | N19: 0.065 | O19: 0.065 | P19: 0.065 | Q19: 0.065 | R19: 0.065 | S19: 0.065 | T19: 0.065 | U19: 0.065 | V19: 0.065
D20: Налог на имущество | E20: % | H20: 0.022 | I20: 0.022 | J20: 0.022 | K20: 0.022 | L20: 0.022 | M20: 0.022 | N20: 0.022 | O20: 0.022 | P20: 0.022 | Q20: 0.022 | R20: 0.022 | S20: 0.022 | T20: 0.022 | U20: 0.022 | V20: 0.022
D21: Страховые отчисления | E21: % | H21: 0.3 | I21: 0.3 | J21: 0.3 | K21: 0.3 | L21: 0.3 | M21: 0.3 | N21: 0.3 | O21: 0.3 | P21: 0.3 | Q21: 0.3 | R21: 0.3 | S21: 0.3 | T21: 0.3 | U21: 0.3 | V21: 0.3
D22: Налог на прибыль | E22: % | H22: 0.2 | I22: 0.2 | J22: 0.2 | K22: 0.2 | L22: 0.2 | M22: 0.2 | N22: 0.2 | O22: 0.2 | P22: 0.2 | Q22: 0.2 | R22: 0.2 | S22: 0.2 | T22: 0.2 | U22: 0.2 | V22: 0.2
D23: Налог на доходы физических лиц (НДФЛ) | E23: % | H23: 0.13 | I23: 0.13 | J23: 0.13 | K23: 0.13 | L23: 0.13 | M23: 0.13 | N23: 0.13 | O23: 0.13 | P23: 0.13 | Q23: 0.13 | R23: 0.13 | S23: 0.13 | T23: 0.13 | U23: 0.13 | V23: 0.13
A25: 3 | B25: Макроэкономические прогнозы
D27: Курс национальной валюты к доллару | E27: руб./$ | H27: 100 | I27: 100 | J27: 100 | K27: 100 | L27: 100 | M27: 100 | N27: 100 | O27: 100 | P27: 100 | Q27: 100 | R27: 100 | S27: 100 | T27: 100 | U27: 100 | V27: 100
D28: Цена на золото | E28: $/Oz | H28: =1100*(1+'Анализ чув-ти'!$C$7) -> 1100 | I28: =1100*(1+'Анализ чув-ти'!$C$7) -> 1100 | J28: =1100*(1+'Анализ чув-ти'!$C$7) -> 1100 | K28: =1100*(1+'Анализ чув-ти'!$C$7) -> 1100 | L28: =1100*(1+'Анализ чув-ти'!$C$7) -> 1100 | M28: =1100*(1+'Анализ чув-ти'!$C$7) -> 1100 | N28: =1100*(1+'Анализ чув-ти'!$C$7) -> 1100 | O28: =1100*(1+'Анализ чув-ти'!$C$7) -> 1100 | ... V28: =1100*(1+'Анализ чув-ти'!$C$7) -> 1100
D29: Цена на золото | E29: руб/грамм | H29: =H28*H$27/$H$7 -> 3536.5821 | I29: =I28*I27/$H$7 -> 3536.5821 | J29: =J28*J27/$H$7 -> 3536.5821 | K29: =K28*K27/$H$7 -> 3536.5821 | L29: =L28*L27/$H$7 -> 3536.5821 | M29: =M28*M27/$H$7 -> 3536.5821 | N29: =N28*N27/$H$7 -> 3536.5821 | O29: =O28*O27/$H$7 -> 3536.5821 | P29: =P28*P27/$H$7 -> 3536.5821 | ... V29: =V28*V27/$H$7 -> 3536.5821
D30: Цена на серебро | E30: $/Oz | H30: 12 | I30: 12 | J30: 12 | K30: 12 | L30: 12 | M30: 12 | N30: 12 | O30: 12 | P30: 12 | Q30: 12 | R30: 12 | S30: 12 | T30: 12 | U30: 12 | V30: 12
D31: Цена на серебро | E31: руб/грамм | H31: =H30*H$27/$H$7 -> 38.580896 | I31: =I30*I$27/$H$7 -> 38.580896 | J31: =J30*J$27/$H$7 -> 38.580896 | K31: =K30*K$27/$H$7 -> 38.580896 | L31: =L30*L$27/$H$7 -> 38.580896 | M31: =M30*M$27/$H$7 -> 38.580896 | N31: =N30*N$27/$H$7 -> 38.580896 | O31: =O30*O$27/$H$7 -> 38.580896 | ... V31: =V30*V$27/$H$7 -> 38.580896
A33: 4 | B33: Цены на ресурсы и материалы, без НДС
D35: Электроэнергия | E35: тыс. руб./МВатт*ч | H35: =10*(1+'Анализ чув-ти'!$C$11) -> 10 | I35: =10*(1+'Анализ чув-ти'!$C$11) -> 10 | J35: =10*(1+'Анализ чув-ти'!$C$11) -> 10 | K35: =10*(1+'Анализ чув-ти'!$C$11) -> 10 | L35: =10*(1+'Анализ чув-ти'!$C$11) -> 10 | M35: =10*(1+'Анализ чув-ти'!$C$11) -> 10 | N35: =10*(1+'Анализ чув-ти'!$C$11) -> 10 | O35: =10*(1+'Анализ чув-ти'!$C$11) -> 10 | ... V35: =10*(1+'Анализ чув-ти'!$C$11) -> 10
D36: Дизельное топливо | E36: тыс. руб./т | H36: =55*(1+'Анализ чув-ти'!$C$11) -> 55 | I36: =55*(1+'Анализ чув-ти'!$C$11) -> 55 | J36: =55*(1+'Анализ чув-ти'!$C$11) -> 55 | K36: =55*(1+'Анализ чув-ти'!$C$11) -> 55 | L36: =55*(1+'Анализ чув-ти'!$C$11) -> 55 | M36: =55*(1+'Анализ чув-ти'!$C$11) -> 55 | N36: =55*(1+'Анализ чув-ти'!$C$11) -> 55 | O36: =55*(1+'Анализ чув-ти'!$C$11) -> 55 | ... V36: =55*(1+'Анализ чув-ти'!$C$11) -> 55
D37: Масла и смазки | E37: тыс. руб./т | H37: =155*(1+'Анализ чув-ти'!$C$11) -> 155 | I37: =155*(1+'Анализ чув-ти'!$C$11) -> 155 | J37: =155*(1+'Анализ чув-ти'!$C$11) -> 155 | K37: =155*(1+'Анализ чув-ти'!$C$11) -> 155 | L37: =155*(1+'Анализ чув-ти'!$C$11) -> 155 | M37: =155*(1+'Анализ чув-ти'!$C$11) -> 155 | N37: =155*(1+'Анализ чув-ти'!$C$11) -> 155 | O37: =155*(1+'Анализ чув-ти'!$C$11) -> 155 | ... V37: =155*(1+'Анализ чув-ти'!$C$11) -> 155
D38: Аммиачная селитра | E38: тыс. руб./т | H38: =25*(1+'Анализ чув-ти'!$C$11) -> 25 | I38: =25*(1+'Анализ чув-ти'!$C$11) -> 25 | J38: =25*(1+'Анализ чув-ти'!$C$11) -> 25 | K38: =25*(1+'Анализ чув-ти'!$C$11) -> 25 | L38: =25*(1+'Анализ чув-ти'!$C$11) -> 25 | M38: =25*(1+'Анализ чув-ти'!$C$11) -> 25 | N38: =25*(1+'Анализ чув-ти'!$C$11) -> 25 | O38: =25*(1+'Анализ чув-ти'!$C$11) -> 25 | ... V38: =25*(1+'Анализ чув-ти'!$C$11) -> 25
D39: Шары для мельниц | E39: тыс. руб./т | H39: =25*(1+'Анализ чув-ти'!$C$11) -> 25 | I39: =25*(1+'Анализ чув-ти'!$C$11) -> 25 | J39: =25*(1+'Анализ чув-ти'!$C$11) -> 25 | K39: =25*(1+'Анализ чув-ти'!$C$11) -> 25 | L39: =25*(1+'Анализ чув-ти'!$C$11) -> 25 | M39: =25*(1+'Анализ чув-ти'!$C$11) -> 25 | N39: =25*(1+'Анализ чув-ти'!$C$11) -> 25 | O39: =25*(1+'Анализ чув-ти'!$C$11) -> 25 | ... V39: =25*(1+'Анализ чув-ти'!$C$11) -> 25
D40: Конвейерная лента | E40: тыс. руб/м2 | H40: =2*(1+'Анализ чув-ти'!$C$11) -> 2 | I40: =2*(1+'Анализ чув-ти'!$C$11) -> 2 | J40: =2*(1+'Анализ чув-ти'!$C$11) -> 2 | K40: =2*(1+'Анализ чув-ти'!$C$11) -> 2 | L40: =2*(1+'Анализ чув-ти'!$C$11) -> 2 | M40: =2*(1+'Анализ чув-ти'!$C$11) -> 2 | N40: =2*(1+'Анализ чув-ти'!$C$11) -> 2 | O40: =2*(1+'Анализ чув-ти'!$C$11) -> 2 | ... V40: =2*(1+'Анализ чув-ти'!$C$11) -> 2
A42: 5 | B42: Прямые затраты на производство единицы продукции в натуральном выражении
D44: Шары для мельниц | E44: г/т | H44: 700
D45: Конвейерная лента | E45: м2/т | H45: 0.005
A47: 6 | B47: Общепроизводственные расходы в натуральном выражении
D49: Электроэнергия (выбранный вариант) | E49: МВатт*ч/год | H49: =CHOOSE($L$9,H55,H56) -> 0 | I49: =CHOOSE($L$9,I55,I56) -> 0 | J49: =CHOOSE($L$9,J55,J56) -> 0 | K49: =CHOOSE($L$9,K55,K56) -> 0 | L49: =CHOOSE($L$9,L55,L56) -> 0 | M49: =CHOOSE($L$9,M55,M56) -> 0 | N49: =CHOOSE($L$9,N55,N56) -> 0 | O49: =CHOOSE($L$9,O55,O56) -> 0 | ... V49: =CHOOSE($L$9,V55,V56) -> 0
D50: Дизельное топливо (выбранный вариант) | E50: т/год | H50: =CHOOSE($L$9,H58,H59) -> 2500 | I50: =CHOOSE($L$9,I58,I59) -> 2500 | J50: =CHOOSE($L$9,J58,J59) -> 2500 | K50: =CHOOSE($L$9,K58,K59) -> 2500 | L50: =CHOOSE($L$9,L58,L59) -> 2500 | M50: =CHOOSE($L$9,M58,M59) -> 2500 | N50: =CHOOSE($L$9,N58,N59) -> 2500 | O50: =CHOOSE($L$9,O58,O59) -> 2500 | ... V50: =CHOOSE($L$9,V58,V59) -> 2500
D51: Масла и смазки | E51: т/год | H51: 100 | I51: 100 | J51: 100 | K51: 100 | L51: 100 | M51: 100 | N51: 100 | O51: 100 | P51: 100 | Q51: 100 | R51: 100 | S51: 100 | T51: 100 | U51: 100 | V51: 100
D52: Аммиачная селитра | E52: т/год | H52: 500 | I52: 500 | J52: 500 | K52: 500 | L52: 500 | M52: 500 | N52: 500 | O52: 500 | P52: 500 | Q52: 500 | R52: 500 | S52: 500 | T52: 500 | U52: 500 | V52: 500
...

Sheet Горный календарь
B1: Параметры модели
D2: Номер периода | H2: =период -> 1 | I2: =период -> 2 | J2: =период -> 3 | K2: =период -> 4 | L2: =период -> 5 | M2: =период -> 6 | N2: =период -> 7 | O2: =период -> 8 | ... V2: =период -> 15
D3: Календарный год | H3: =период_знач -> 2020 | I3: =период_знач -> 2021 | J3: =период_знач -> 2022 | K3: =период_знач -> 2023 | L3: =период_знач -> 2024 | M3: =период_знач -> 2025 | N3: =период_знач -> 2026 | O3: =период_знач -> 2027 | ... V3: =период_знач -> 2034
A5: 1 | B5: Добыча
D7: Добыча руды | E7: тыс. т. | H7: 0 | I7: 0 | J7: 150 | K7: 300 | L7: 300 | M7: 300 | N7: 300 | O7: 300 | P7: 300 | Q7: 300 | R7: 300 | S7: 300 | T7: 300 | U7: 300 | V7: 300
D8: Добыча руды | E8: тыс. м3 | H8: 0 | I8: 0 | J8: 60 | K8: 120 | L8: 120 | M8: 120 | N8: 120 | O8: 120 | P8: 120 | Q8: 120 | R8: 120 | S8: 120 | T8: 120 | U8: 120 | V8: 120
D9: Вскрыша | E9: тыс. м3 | H9: 0 | I9: 0 | J9: 468 | K9: 936 | L9: 936 | M9: 936 | N9: 936 | O9: 936 | P9: 936 | Q9: 936 | R9: 936 | S9: 936 | T9: 936 | U9: 936 | V9: 936
D10: Содержание золота в руде | E10: г/т | H10: 0 | I10: 0 | J10: 2.8 | K10: 2.7 | L10: 2.9 | M10: 3.5 | N10: 3.2 | O10: 2.7 | P10: 2.6 | Q10: 2.6 | R10: 2.5 | S10: 2.5 | T10: 2.4 | U10: 2.4 | V10: 2.4
D11: Содержание серебра в руде | E11: г/т | H11: 0 | I11: 0 | J11: 5.5 | K11: 5.4 | L11: 5.6 | M11: 5.6 | N11: 5.6 | O11: 5.6 | P11: 5.6 | Q11: 5.6 | R11: 5.6 | S11: 5.5 | T11: 5.5 | U11: 5.5 | V11: 5.5
D12: Извлечение золота на фабрике | E12: % | H12: 0.8 | I12: 0.8 | J12: 0.8 | K12: 0.8 | L12: 0.8 | M12: 0.8 | N12: 0.8 | O12: 0.8 | P12: 0.8 | Q12: 0.8 | R12: 0.8 | S12: 0.8 | T12: 0.8 | U12: 0.8 | V12: 0.8
D13: Извлечение серебра на фабрике | E13: % | H13: 0.85 | I13: 0.85 | J13: 0.85 | K13: 0.85 | L13: 0.85 | M13: 0.85 | N13: 0.85 | O13: 0.85 | P13: 0.85 | Q13: 0.85 | R13: 0.85 | S13: 0.85 | T13: 0.85 | U13: 0.85 | V13: 0.85

Sheet CAPEX
B1: Параметры модели
D2: Номер периода | H2: =период -> 1 | I2: =период -> 2 | J2: =период -> 3 | K2: =период -> 4 | L2: =период -> 5 | M2: =период -> 6 | N2: =период -> 7 | O2: =период -> 8 | ... V2: =период -> 15
D3: Календарный год | H3: =период_знач -> 2020 | I3: =период_знач -> 2021 | J3: =период_знач -> 2022 | K3: =период_знач -> 2023 | L3: =период_знач -> 2024 | M3: =период_знач -> 2025 | N3: =период_знач -> 2026 | O3: =период_знач -> 2027 | ... V3: =период_знач -> 2034
A5: 1 | B5: Справочно
D7: Курс национальной валюты к доллару | E7: руб./$ | H7: =курс -> 100 | I7: =курс -> 100 | J7: =курс -> 100 | K7: =курс -> 100 | L7: =курс -> 100 | M7: =курс -> 100 | N7: =курс -> 100 | O7: =курс -> 100 | ... V7: =курс -> 100
D8: Сценарий | H8: ='Исходные данные'!H9:K9 -> Собственная электростанция | L8: ='Исходные данные'!L9 -> 2
A10: 2 | B10: Инвестиционная программа (без НДС)
D12: Здания и сооружения | E12: тыс. руб. | I12: 300000 | J12: 150000
D13: Горная техника, в т.ч. | E13: тыс. руб. | H13: =H14+H15*H7 -> 0 | I13: =I14+I15*I7 -> 350000 | J13: =J14+J15*J7 -> 0 | K13: =K14+K15*K7 -> 0 | L13: =L14+L15*L7 -> 0 | M13: =M14+M15*M7 -> 0 | N13: =N14+N15*N7 -> 0 | O13: =O14+O15*O7 -> 0 | ... V13: =V14+V15*V7 -> 0
D14: Отечественная | E14: тыс. руб. | I14: 50000
D15: Импортная | E15: тыс. $ | I15: 3000
D16: Технологическое оборудование, в т.ч. | E16: тыс. руб. | H16: =H17+H18*H7 -> 0 | I16: =I17+I18*I7 -> 370000 | J16: =J17+J18*J7 -> 50000 | K16: =K17+K18*K7 -> 0 | L16: =L17+L18*L7 -> 0 | M16: =M17+M18*M7 -> 0 | N16: =N17+N18*N7 -> 0 | O16: =O17+O18*O7 -> 0 | ... V16: =V17+V18*V7 -> 0
D17: Отечественное | E17: тыс. руб. | I17: 70000
D18: Импортное | E18: тыс. $ | I18: 3000 | J18: 500
D19: Приобретение прочих основных средств | E19: тыс. руб. | I19: =CHOOSE($L$8,0,50000) -> 50000 | J19: 75000 | K19: 45000
D20: Проектирование и защита проекта | E20: тыс. руб. | H20: 40000
A23: 3 | B23: Срок эксплуатации ОС
D25: Срок использования вводимых в эксплуатацию ОС | E25: лет | H25: 20

Sheet Выручка
B1: Параметры модели
D2: Номер периода | H2: =период -> 1 | I2: =период -> 2 | J2: =период -> 3 | K2: =период -> 4 | L2: =период -> 5 | M2: =период -> 6 | N2: =период -> 7 | O2: =период -> 8 | ... V2: =период -> 15
D3: Календарный год | H3: =период_знач -> 2020 | I3: =период_знач -> 2021 | J3: =период_знач -> 2022 | K3: =период_знач -> 2023 | L3: =период_знач -> 2024 | M3: =период_знач -> 2025 | N3: =период_знач -> 2026 | O3: =период_знач -> 2027 | ... V3: =период_знач -> 2034
A5: 1 | B5: Переработка и извлечение
D7: Переработка руды | E7: тыс. т | H7: ='Горный календарь'!H7 -> 0 | I7: ='Горный календарь'!I7 -> 0 | J7: ='Горный календарь'!J7 -> 150 | K7: ='Горный календарь'!K7 -> 300 | L7: ='Горный календарь'!L7 -> 300 | M7: ='Горный календарь'!M7 -> 300 | N7: ='Горный календарь'!N7 -> 300 | O7: ='Горный календарь'!O7 -> 300 | ... V7: ='Горный календарь'!V7 -> 300
D8: Содержание золота в руде | E8: г/т | H8: ='Горный календарь'!H10 -> 0 | I8: ='Горный календарь'!I10 -> 0 | J8: ='Горный календарь'!J10 -> 2.8 | K8: ='Горный календарь'!K10 -> 2.7 | L8: ='Горный календарь'!L10 -> 2.9 | M8: ='Горный календарь'!M10 -> 3.5 | N8: ='Горный календарь'!N10 -> 3.2 | O8: ='Горный календарь'!O10 -> 2.7 | ... V8: ='Горный календарь'!V10 -> 2.4
D9: Содержание серебра в руде | E9: г/т | H9: ='Горный календарь'!H11 -> 0 | I9: ='Горный календарь'!I11 -> 0 | J9: ='Горный календарь'!J11 -> 5.5 | K9: ='Горный календарь'!K11 -> 5.4 | L9: ='Горный календарь'!L11 -> 5.6 | M9: ='Горный календарь'!M11 -> 5.6 | N9: ='Горный календарь'!N11 -> 5.6 | O9: ='Горный календарь'!O11 -> 5.6 | ... V9: ='Горный календарь'!V11 -> 5.5
D10: Извлечение золота на фабрике | E10: % | H10: ='Горный календарь'!H12 -> 0.8 | I10: ='Горный календарь'!I12 -> 0.8 | J10: ='Горный календарь'!J12 -> 0.8 | K10: ='Горный календарь'!K12 -> 0.8 | L10: ='Горный календарь'!L12 -> 0.8 | M10: ='Горный календарь'!M12 -> 0.8 | N10: ='Горный календарь'!N12 -> 0.8 | O10: ='Горный календарь'!O12 -> 0.8 | ... V10: ='Горный календарь'!V12 -> 0.8
D11: Извлечение серебра на фабрике | E11: % | H11: ='Горный календарь'!H13 -> 0.85 | I11: ='Горный календарь'!I13 -> 0.85 | J11: ='Горный календарь'!J13 -> 0.85 | K11: ='Горный календарь'!K13 -> 0.85 | L11: ='Горный календарь'!L13 -> 0.85 | M11: ='Горный календарь'!M13 -> 0.85 | N11: ='Горный календарь'!N13 -> 0.85 | O11: ='Горный календарь'!O13 -> 0.85 | ... V11: ='Горный календарь'!V13 -> 0.85
A13: 2 | B13: Продажа драгоценных металлов
D15: Всего товарного золота | E15: г | H15: =H7*H8*H10 -> 0 | I15: =I7*I8*I10 -> 0 | J15: =J7*J8*J10 -> 336 | K15: =K7*K8*K10 -> 648 | L15: =L7*L8*L10 -> 696 | M15: =M7*M8*M10 -> 840 | N15: =N7*N8*N10 -> 768 | O15: =O7*O8*O10 -> 648 | ... V15: =V7*V8*V10 -> 576
D16: Всего товарного серебра | E16: г | H16: =H7*H9*H11 -> 0 | I16: =I7*I9*I11 -> 0 | J16: =J7*J9*J11 -> 701.25 | K16: =K7*K9*K11 -> 1377 | L16: =L7*L9*L11 -> 1428 | M16: =M7*M9*M11 -> 1428 | N16: =N7*N9*N11 -> 1428 | O16: =O7*O9*O11 -> 1428 | ... V16: =V7*V9*V11 -> 1402.5
D17: Цена золота | E17: руб./г | H17: ='Исходные данные'!H29 -> 3536.5821 | I17: ='Исходные данные'!I29 -> 3536.5821 | J17: ='Исходные данные'!J29 -> 3536.5821 | K17: ='Исходные данные'!K29 -> 3536.5821 | L17: ='Исходные данные'!L29 -> 3536.5821 | M17: ='Исходные данные'!M29 -> 3536.5821 | N17: ='Исходные данные'!N29 -> 3536.5821 | O17: ='Исходные данные'!O29 -> 3536.5821 | ... V17: ='Исходные данные'!V29 -> 3536.5821
D18: Цена серебра | E18: руб./г | H18: ='Исходные данные'!H31 -> 38.580896 | I18: ='Исходные данные'!I31 -> 38.580896 | J18: ='Исходные данные'!J31 -> 38.580896 | K18: ='Исходные данные'!K31 -> 38.580896 | L18: ='Исходные данные'!L31 -> 38.580896 | M18: ='Исходные данные'!M31 -> 38.580896 | N18: ='Исходные данные'!N31 -> 38.580896 | O18: ='Исходные данные'!O31 -> 38.580896 | ... V18: ='Исходные данные'!V31 -> 38.580896
D19: Выручка золото | E19: руб. | H19: =H15*H17 -> 0 | I19: =I15*I17 -> 0 | J19: =J15*J17 -> 1188291.6 | K19: =K15*K17 -> 2291705.2 | L19: =L15*L17 -> 2461461.2 | M19: =M15*M17 -> 2970729 | N19: =N15*N17 -> 2716095.1 | O19: =O15*O17 -> 2291705.2 | ... V19: =V15*V17 -> 2037071.3
D20: Выручка серебро | E20: руб. | H20: =H16*H18 -> 0 | I20: =I16*I18 -> 0 | J20: =J16*J18 -> 27054.853 | K20: =K16*K18 -> 53125.894 | L20: =L16*L18 -> 55093.519 | M20: =M16*M18 -> 55093.519 | N20: =N16*N18 -> 55093.519 | O20: =O16*O18 -> 55093.519 | ... V20: =V16*V18 -> 54109.706

Sheet OPEX
B1: Параметры модели
D2: Номер периода | H2: =период -> 1 | I2: =период -> 2 | J2: =период -> 3 | K2: =период -> 4 | L2: =период -> 5 | M2: =период -> 6 | N2: =период -> 7 | O2: =период -> 8 | ... V2: =период -> 15
D3: Календарный год | H3: =период_знач -> 2020 | I3: =период_знач -> 2021 | J3: =период_знач -> 2022 | K3: =период_знач -> 2023 | L3: =период_знач -> 2024 | M3: =период_знач -> 2025 | N3: =период_знач -> 2026 | O3: =период_знач -> 2027 | ... V3: =период_знач -> 2034
A5: 1 | B5: Справочно
D7: Перерботка на обогатительной фабрике | E7: тыс. тонн | H7: ='Горный календарь'!H7 -> 0 | I7: ='Горный календарь'!I7 -> 0 | J7: ='Горный календарь'!J7 -> 150 | K7: ='Горный календарь'!K7 -> 300 | L7: ='Горный календарь'!L7 -> 300 | M7: ='Горный календарь'!M7 -> 300 | N7: ='Горный календарь'!N7 -> 300 | O7: ='Горный календарь'!O7 -> 300 | ... V7: ='Горный календарь'!V7 -> 300
D8: Первоначальная стоимость материальных ОС | E8: тыс. руб. | H8: =SUM(CAPEX!$H$12:H13,CAPEX!$H$16:H16,CAPEX!$H$19:H19) -> 0 | I8: =SUM(CAPEX!$H$12:I13,CAPEX!$H$16:I16,CAPEX!$H$19:I19) -> 1070000 | J8: =SUM(CAPEX!$H$12:J13,CAPEX!$H$16:J16,CAPEX!$H$19:J19) -> 1345000 | K8: =SUM(CAPEX!$H$12:K13,CAPEX!$H$16:K16,CAPEX!$H$19:K19) -> 1390000 | L8: =SUM(CAPEX!$H$12:L13,CAPEX!$H$16:L16,CAPEX!$H$19:L19) -> 1390000 | M8: =SUM(CAPEX!$H$12:M13,CAPEX!$H$16:M16,CAPEX!$H$19:M19) -> 1390000 | N8: =SUM(CAPEX!$H$12:N13,CAPEX!$H$16:N16,CAPEX!$H$19:N19) -> 1390000 | O8: =SUM(CAPEX!$H$12:O13,CAPEX!$H$16:O16,CAPEX!$H$19:O19) -> 1390000 | ... V8: =SUM(CAPEX!$H$12:V13,CAPEX!$H$16:V16,CAPEX!$H$19:V19) -> 1390000
A10: 2 | B10: Прямые затраты на производство продукции
D12: Шары для мельниц | E12: тыс. руб. | H12: =H$7*'Исходные данные'!$H$44*'Исходные данные'!H39/1000 -> 0 | I12: =I$7*'Исходные данные'!$H$44*'Исходные данные'!I39/1000 -> 0 | J12: =J$7*'Исходные данные'!$H$44*'Исходные данные'!J39/1000 -> 2625 | K12: =K$7*'Исходные данные'!$H$44*'Исходные данные'!K39/1000 -> 5250 | L12: =L$7*'Исходные данные'!$H$44*'Исходные данные'!L39/1000 -> 5250 | M12: =M$7*'Исходные данные'!$H$44*'Исходные данные'!M39/1000 -> 5250 | N12: =N$7*'Исходные данные'!$H$44*'Исходные данные'!N39/1000 -> 5250 | O12: =O$7*'Исходные данные'!$H$44*'Исходные данные'!O39/1000 -> 5250 | ... V12: =V$7*'Исходные данные'!$H$44*'Исходные данные'!V39/1000 -> 5250
D13: Конвейерная лента | E13: тыс. руб. | H13: =H$7*'Исходные данные'!$H$45*'Исходные данные'!H40*1000 -> 0 | I13: =I$7*'Исходные данные'!$H$45*'Исходные данные'!I40*1000 -> 0 | J13: =J$7*'Исходные данные'!$H$45*'Исходные данные'!J40*1000 -> 1500 | K13: =K$7*'Исходные данные'!$H$45*'Исходные данные'!K40*1000 -> 3000 | L13: =L$7*'Исходные данные'!$H$45*'Исходные данные'!L40*1000 -> 3000 | M13: =M$7*'Исходные данные'!$H$45*'Исходные данные'!M40*1000 -> 3000 | N13: =N$7*'Исходные данные'!$H$45*'Исходные данные'!N40*1000 -> 3000 | O13: =O$7*'Исходные данные'!$H$45*'Исходные данные'!O40*1000 -> 3000 | ... V13: =V$7*'Исходные данные'!$H$45*'Исходные данные'!V40*1000 -> 3000
A15: 3 | B15: Общепроизводственные расходы
D17: Электроэнергия (выбранный вариант) | E17: тыс. руб. | H17: ='Исходные данные'!H49*'Исходные данные'!H35 -> 0 | I17: ='Исходные данные'!I49*'Исходные данные'!I35 -> 0 | J17: ='Исходные данные'!J49*'Исходные данные'!J35 -> 0 | K17: ='Исходные данные'!K49*'Исходные данные'!K35 -> 0 | L17: ='Исходные данные'!L49*'Исходные данные'!L35 -> 0 | M17: ='Исходные данные'!M49*'Исходные данные'!M35 -> 0 | N17: ='Исходные данные'!N49*'Исходные данные'!N35 -> 0 | O17: ='Исходные данные'!O49*'Исходные данные'!O35 -> 0 | ... V17: ='Исходные данные'!V49*'Исходные данные'!V35 -> 0
D18: Дизельное топливо (выбранный вариант) | E18: тыс. руб. | H18: ='Исходные данные'!H50*'Исходные данные'!H36 -> 137500 | I18: ='Исходные данные'!I50*'Исходные данные'!I36 -> 137500 | J18: ='Исходные данные'!J50*'Исходные данные'!J36 -> 137500 | K18: ='Исходные данные'!K50*'Исходные данные'!K36 -> 137500 | L18: ='Исходные данные'!L50*'Исходные данные'!L36 -> 137500 | M18: ='Исходные данные'!M50*'Исходные данные'!M36 -> 137500 | N18: ='Исходные данные'!N50*'Исходные данные'!N36 -> 137500 | O18: ='Исходные данные'!O50*'Исходные данные'!O36 -> 137500 | ... V18: ='Исходные данные'!V50*'Исходные данные'!V36 -> 137500
D19: Масла и смазки | E19: тыс. руб. | H19: ='Исходные данные'!H51*'Исходные данные'!H37 -> 15500 | I19: ='Исходные данные'!I51*'Исходные данные'!I37 -> 15500 | J19: ='Исходные данные'!J51*'Исходные данные'!J37 -> 15500 | K19: ='Исходные данные'!K51*'Исходные данные'!K37 -> 15500 | L19: ='Исходные данные'!L51*'Исходные данные'!L37 -> 15500 | M19: ='Исходные данные'!M51*'Исходные данные'!M37 -> 15500 | N19: ='Исходные данные'!N51*'Исходные данные'!N37 -> 15500 | O19: ='Исходные данные'!O51*'Исходные данные'!O37 -> 15500 | ... V19: ='Исходные данные'!V51*'Исходные данные'!V37 -> 15500
D20: Аммиачная селитра | E20: тыс. руб. | H20: ='Исходные данные'!H52*'Исходные данные'!H38 -> 12500 | I20: ='Исходные данные'!I52*'Исходные данные'!I38 -> 12500 | J20: ='Исходные данные'!J52*'Исходные данные'!J38 -> 12500 | K20: ='Исходные данные'!K52*'Исходные данные'!K38 -> 12500 | L20: ='Исходные данные'!L52*'Исходные данные'!L38 -> 12500 | M20: ='Исходные данные'!M52*'Исходные данные'!M38 -> 12500 | N20: ='Исходные данные'!N52*'Исходные данные'!N38 -> 12500 | O20: ='Исходные данные'!O52*'Исходные данные'!O38 -> 12500 | ... V20: ='Исходные данные'!V52*'Исходные данные'!V38 -> 12500
D21: Ремонт и обслуживание ОС (% от первоначальной ст-ти) | E21: тыс. руб. | H21: ='Исходные данные'!H53*H8 -> 0 | I21: ='Исходные данные'!I53*I8 -> 32100 | J21: ='Исходные данные'!J53*J8 -> 40350 | K21: ='Исходные данные'!K53*K8 -> 41700 | L21: ='Исходные данные'!L53*L8 -> 41700 | M21: ='Исходные данные'!M53*M8 -> 41700 | N21: ='Исходные данные'!N53*N8 -> 41700 | O21: ='Исходные данные'!O53*O8 -> 41700 | ... V21: ='Исходные данные'!V53*V8 -> 41700
A23: 4 | B23: Коммерческие и управленческие расходы
D25: Административно-хозяйственные расходы | E25: тыс. руб. | H25: ='Исходные данные'!H63 -> 20000 | I25: ='Исходные данные'!I63 -> 20000 | J25: ='Исходные данные'!J63 -> 20000 | K25: ='Исходные данные'!K63 -> 20000 | L25: ='Исходные данные'!L63 -> 20000 | M25: ='Исходные данные'!M63 -> 20000 | N25: ='Исходные данные'!N63 -> 20000 | O25: ='Исходные данные'!O63 -> 20000 | ... V25: ='Исходные данные'!V63 -> 20000
D26: Доставка продукции до аффинажного завода | E26: тыс. руб. | H26: ='Исходные данные'!H64*H7/MAX($H$7:$V$7) -> 0 | I26: ='Исходные данные'!I64*I7/MAX($H$7:$V$7) -> 0 | J26: ='Исходные данные'!J64*J7/MAX($H$7:$V$7) -> 2500 | K26: ='Исходные данные'!K64*K7/MAX($H$7:$V$7) -> 5000 | L26: ='Исходные данные'!L64*L7/MAX($H$7:$V$7) -> 5000 | M26: ='Исходные данные'!M64*M7/MAX($H$7:$V$7) -> 5000 | N26: ='Исходные данные'!N64*N7/MAX($H$7:$V$7) -> 5000 | O26: ='Исходные данные'!O64*O7/MAX($H$7:$V$7) -> 5000 | ... V26: ='Исходные данные'!V64*V7/MAX($H$7:$V$7) -> 5000
D27: Расходы на доставку вахты | E27: тыс. руб. | H27: ='Исходные данные'!H65*H7/MAX($H$7:$V$7) -> 0 | I27: ='Исходные данные'!I65*I7/MAX($H$7:$V$7) -> 0 | J27: ='Исходные данные'!J65*J7/MAX($H$7:$V$7) -> 2500 | K27: ='Исходные данные'!K65*K7/MAX($H$7:$V$7) -> 5000 | L27: ='Исходные данные'!L65*L7/MAX($H$7:$V$7) -> 5000 | M27: ='Исходные данные'!M65*M7/MAX($H$7:$V$7) -> 5000 | N27: ='Исходные данные'!N65*N7/MAX($H$7:$V$7) -> 5000 | O27: ='Исходные данные'!O65*O7/MAX($H$7:$V$7) -> 5000 | ... V27: ='Исходные данные'!V65*V7/MAX($H$7:$V$7) -> 5000
A29: 5 | B29: Прочие расходы
D31: Стоимость аффинажа | E31: тыс. руб. | H31: ='Исходные данные'!H69*SUM(Выручка!H19:H20) -> 0 | I31: ='Исходные данные'!I69*SUM(Выручка!I19:I20) -> 0 | J31: ='Исходные данные'!J69*SUM(Выручка!J19:J20) -> 6076.7322 | K31: ='Исходные данные'!K69*SUM(Выручка!K19:K20) -> 11724.156 | L31: ='Исходные данные'!L69*SUM(Выручка!L19:L20) -> 12582.773 | M31: ='Исходные данные'!M69*SUM(Выручка!M19:M20) -> 15129.113 | N31: ='Исходные данные'!N69*SUM(Выручка!N19:N20) -> 13855.943 | O31: ='Исходные данные'!O69*SUM(Выручка!O19:O20) -> 11733.994 | ... V31: ='Исходные данные'!V69*SUM(Выручка!V19:V20) -> 10455.905
D32: Услуги банка при продаже драгоценных металлов | E32: тыс. руб. | H32: ='Исходные данные'!H70*SUM(Выручка!H19:H20) -> 0 | I32: ='Исходные данные'!I70*SUM(Выручка!I19:I20) -> 0 | J32: ='Исходные данные'!J70*SUM(Выручка!J19:J20) -> 2430.6929 | K32: ='Исходные данные'!K70*SUM(Выручка!K19:K20) -> 4689.6622 | L32: ='Исходные данные'!L70*SUM(Выручка!L19:L20) -> 5033.1094 | M32: ='Исходные данные'!M70*SUM(Выручка!M19:M20) -> 6051.645 | N32: ='Исходные данные'!N70*SUM(Выручка!N19:N20) -> 5542.3772 | O32: ='Исходные данные'!O70*SUM(Выручка!O19:O20) -> 4693.5975 | ... V32: ='Исходные данные'!V70*SUM(Выручка!V19:V20) -> 4182.362
A34: 6 | B34: Оплата труда
D36: Административно-управленический персонал | E36: тыс. руб. | H36: ='Исходные данные'!H79 -> 50000 | I36: ='Исходные данные'!I79 -> 50000 | J36: ='Исходные данные'!J79 -> 50000 | K36: ='Исходные данные'!K79 -> 50000 | L36: ='Исходные данные'!L79 -> 50000 | M36: ='Исходные данные'!M79 -> 50000 | N36: ='Исходные данные'!N79 -> 50000 | O36: ='Исходные данные'!O79 -> 50000 | ... V36: ='Исходные данные'!V79 -> 50000
D37: Производственный персонал | E37: тыс. руб. | H37: ='Исходные данные'!H80*H7/MAX($H$7:$V$7) -> 0 | I37: ='Исходные данные'!I80*I7/MAX($H$7:$V$7) -> 0 | J37: ='Исходные данные'!J80*J7/MAX($H$7:$V$7) -> 50000 | K37: ='Исходные данные'!K80*K7/MAX($H$7:$V$7) -> 100000 | L37: ='Исходные данные'!L80*L7/MAX($H$7:$V$7) -> 100000 | M37: ='Исходные данные'!M80*M7/MAX($H$7:$V$7) -> 100000 | N37: ='Исходные данные'!N80*N7/MAX($H$7:$V$7) -> 100000 | O37: ='Исходные данные'!O80*O7/MAX($H$7:$V$7) -> 100000 | ... V37: ='Исходные данные'!V80*V7/MAX($H$7:$V$7) -> 100000
D38: Вспомогательный персонал (выбранный вариант) | E38: тыс. руб. | H38: ='Исходные данные'!H81*H7/MAX($H$7:$V$7) -> 0 | I38: ='Исходные данные'!I81*I7/MAX($H$7:$V$7) -> 0 | J38: ='Исходные данные'!J81*J7/MAX($H$7:$V$7) -> 55000 | K38: ='Исходные данные'!K81*K7/MAX($H$7:$V$7) -> 110000 | L38: ='Исходные данные'!L81*L7/MAX($H$7:$V$7) -> 110000 | M38: ='Исходные данные'!M81*M7/MAX($H$7:$V$7) -> 110000 | N38: ='Исходные данные'!N81*N7/MAX($H$7:$V$7) -> 110000 | O38: ='Исходные данные'!O81*O7/MAX($H$7:$V$7) -> 110000 | ... V38: ='Исходные данные'!V81*V7/MAX($H$7:$V$7) -> 110000
A40: 7 | B40: Всего затрат
D42: Всего операционных затрат | E42: тыс. руб. | H42: =SUM(H12:H13,H17:H21,H25:H27,H31:H32,H36:H38) -> 235500 | I42: =SUM(I12:I13,I17:I21,I25:I27,I31:I32,I36:I38) -> 267600 | J42: =SUM(J12:J13,J17:J21,J25:J27,J31:J32,J36:J38) -> 398482.43 | K42: =SUM(K12:K13,K17:K21,K25:K27,K31:K32,K36:K38) -> 521863.82 | L42: =SUM(L12:L13,L17:L21,L25:L27,L31:L32,L36:L38) -> 523065.88 | M42: =SUM(M12:M13,M17:M21,M25:M27,M31:M32,M36:M38) -> 526630.76 | N42: =SUM(N12:N13,N17:N21,N25:N27,N31:N32,N36:N38) -> 524848.32 | O42: =SUM(O12:O13,O17:O21,O25:O27,O31:O32,O36:O38) -> 521877.59 | ... V42: =SUM(V12:V13,V17:V21,V25:V27,V31:V32,V36:V38) -> 520088.27
D43: НДС | E43: тыс. руб. | H43: ='Исходные данные'!H14*SUM(H12:H13,H17:H21,H25:H27,H31:H32) -> 37100 | I43: ='Исходные данные'!I14*SUM(I12:I13,I17:I21,I25:I27,I31:I32) -> 43520 | J43: ='Исходные данные'!J14*SUM(J12:J13,J17:J21,J25:J27,J31:J32) -> 48696.485 | K43: ='Исходные данные'!K14*SUM(K12:K13,K17:K21,K25:K27,K31:K32) -> 52372.764 | L43: ='Исходные данные'!L14*SUM(L12:L13,L17:L21,L25:L27,L31:L32) -> 52613.177 | M43: ='Исходные данные'!M14*SUM(M12:M13,M17:M21,M25:M27,M31:M32) -> 53326.152 | N43: ='Исходные данные'!N14*SUM(N12:N13,N17:N21,N25:N27,N31:N32) -> 52969.664 | O43: ='Исходные данные'!O14*SUM(O12:O13,O17:O21,O25:O27,O31:O32) -> 52375.518 | ... V43: ='Исходные данные'!V14*SUM(V12:V13,V17:V21,V25:V27,V31:V32) -> 52017.653
D44: НДФЛ | E44: тыс. руб. | H44: =SUM(H36:H38)*'Исходные данные'!H23 -> 6500 | I44: =SUM(I36:I38)*'Исходные данные'!I23 -> 6500 | J44: =SUM(J36:J38)*'Исходные данные'!J23 -> 20150 | K44: =SUM(K36:K38)*'Исходные данные'!K23 -> 33800 | L44: =SUM(L36:L38)*'Исходные данные'!L23 -> 33800 | M44: =SUM(M36:M38)*'Исходные данные'!M23 -> 33800 | N44: =SUM(N36:N38)*'Исходные данные'!N23 -> 33800 | O44: =SUM(O36:O38)*'Исходные данные'!O23 -> 33800 | ... V44: =SUM(V36:V38)*'Исходные данные'!V23 -> 33800
D45: Социальные отчисления | E45: тыс. руб. | H45: ='Исходные данные'!H21*SUM(H36:H38) -> 15000 | I45: ='Исходные данные'!I21*SUM(I36:I38) -> 15000 | J45: ='Исходные данные'!J21*SUM(J36:J38) -> 46500 | K45: ='Исходные данные'!K21*SUM(K36:K38) -> 78000 | L45: ='Исходные данные'!L21*SUM(L36:L38) -> 78000 | M45: ='Исходные данные'!M21*SUM(M36:M38) -> 78000 | N45: ='Исходные данные'!N21*SUM(N36:N38) -> 78000 | O45: ='Исходные данные'!O21*SUM(O36:O38) -> 78000 | ... V45: ='Исходные данные'!V21*SUM(V36:V38) -> 78000
A47: 8 | B47: Вложения в оборотные средства
D49: Норма оборотных средств | E49: тыс. руб. | H49: =IF(H7<=0,0,SUM(H42:H45)*'Исходные данные'!H88) -> 0 | I49: =IF(I7<=0,0,SUM(I42:I45)*'Исходные данные'!I88) -> 0 | J49: =IF(J7<=0,0,SUM(J42:J45)*'Исходные данные'!J88) -> 154148.67 | K49: =IF(K7<=0,0,SUM(K42:K45)*'Исходные данные'!K88) -> 205810.97 | L49: =IF(L7<=0,0,SUM(L42:L45)*'Исходные данные'!L88) -> 206243.72 | M49: =IF(M7<=0,0,SUM(M42:M45)*'Исходные данные'!M88) -> 207527.07 | N49: =IF(N7<=0,0,SUM(N42:N45)*'Исходные данные'!N88) -> 206885.4 | O49: =IF(O7<=0,0,SUM(O42:O45)*'Исходные данные'!O88) -> 205815.93 | ... U49: =IF(U7<=0,0,SUM(U42:U45)*'Исходные данные'!U88) -> 205171.78
D50: Изменение оборотных средств | E50: тыс. руб. | H50: =H49-G49 -> 0 | I50: =I49-H49 -> 0 | J50: =J49-I49 -> 154148.67 | K50: =K49-J49 -> 51662.301 | L50: =L49-K49 -> 432.74339 | M50: =M49-L49 -> 1283.3549 | N50: =N49-M49 -> -641.67746 | O50: =O49-N49 -> -1069.4624 | ... V50: =V49-U49 -> -205171.78

Sheet Налоги
B1: Параметры модели
D2: Номер периода | H2: =период -> 1 | I2: =период -> 2 | J2: =период -> 3 | K2: =период -> 4 | L2: =период -> 5 | M2: =период -> 6 | N2: =период -> 7 | O2: =период -> 8 | ... V2: =период -> 15
D3: Календарный год | H3: =период_знач -> 2020 | I3: =период_знач -> 2021 | J3: =период_знач -> 2022 | K3: =период_знач -> 2023 | L3: =период_знач -> 2024 | M3: =период_знач -> 2025 | N3: =период_знач -> 2026 | O3: =период_знач -> 2027 | ... V3: =период_знач -> 2034
A5: 1 | B5: НДПИ
D7: Выручка серебро | E7: тыс. руб. | H7: =Выручка!H20 -> 0 | I7: =Выручка!I20 -> 0 | J7: =Выручка!J20 -> 27054.853 | K7: =Выручка!K20 -> 53125.894 | L7: =Выручка!L20 -> 55093.519 | M7: =Выручка!M20 -> 55093.519 | N7: =Выручка!N20 -> 55093.519 | O7: =Выручка!O20 -> 55093.519 | ... V7: =Выручка!V20 -> 54109.706
D8: НДПИ серебро | E8: тыс. руб. | H8: =H7*'Исходные данные'!H19 -> 0 | I8: =I7*'Исходные данные'!I19 -> 0 | J8: =J7*'Исходные данные'!J19 -> 1758.5655 | K8: =K7*'Исходные данные'!K19 -> 3453.1831 | L8: =L7*'Исходные данные'!L19 -> 3581.0788 | M8: =M7*'Исходные данные'!M19 -> 3581.0788 | N8: =N7*'Исходные данные'!N19 -> 3581.0788 | O8: =O7*'Исходные данные'!O19 -> 3581.0788 | ... V8: =V7*'Исходные данные'!V19 -> 3517.1309
D9: Выручка золото | E9: тыс. руб. | H9: =Выручка!H19 -> 0 | I9: =Выручка!I19 -> 0 | J9: =Выручка!J19 -> 1188291.6 | K9: =Выручка!K19 -> 2291705.2 | L9: =Выручка!L19 -> 2461461.2 | M9: =Выручка!M19 -> 2970729 | N9: =Выручка!N19 -> 2716095.1 | O9: =Выручка!O19 -> 2291705.2 | ... V9: =Выручка!V19 -> 2037071.3
D10: НДПИ золото | E10: тыс. руб. | H10: =H9*'Исходные данные'!H18 -> 0 | I10: =I9*'Исходные данные'!I18 -> 0 | J10: =J9*'Исходные данные'!J18 -> 71297.496 | K10: =K9*'Исходные данные'!K18 -> 137502.31 | L10: =L9*'Исходные данные'!L18 -> 147687.67 | M10: =M9*'Исходные данные'!M18 -> 178243.74 | N10: =N9*'Исходные данные'!N18 -> 162965.7 | O10: =O9*'Исходные данные'!O18 -> 137502.31 | ... V10: =V9*'Исходные данные'!V18 -> 122224.28
A12: 2 | B12: Налог на имущество
D14: Первоначальная стоимость ОС на конец периода | E14: тыс. руб. | H14: =SUM(CAPEX!$H$12:H13,CAPEX!$H$16:H16,CAPEX!$H$19:H20) -> 40000 | I14: =SUM(CAPEX!$H$12:I13,CAPEX!$H$16:I16,CAPEX!$H$19:I20) -> 1110000 | J14: =SUM(CAPEX!$H$12:J13,CAPEX!$H$16:J16,CAPEX!$H$19:J20) -> 1385000 | K14: =SUM(CAPEX!$H$12:K13,CAPEX!$H$16:K16,CAPEX!$H$19:K20) -> 1430000 | L14: =SUM(CAPEX!$H$12:L13,CAPEX!$H$16:L16,CAPEX!$H$19:L20) -> 1430000 | M14: =SUM(CAPEX!$H$12:M13,CAPEX!$H$16:M16,CAPEX!$H$19:M20) -> 1430000 | N14: =SUM(CAPEX!$H$12:N13,CAPEX!$H$16:N16,CAPEX!$H$19:N20) -> 1430000 | O14: =SUM(CAPEX!$H$12:O13,CAPEX!$H$16:O16,CAPEX!$H$19:O20) -> 1430000 | ... V14: =SUM(CAPEX!$H$12:V13,CAPEX!$H$16:V16,CAPEX!$H$19:V20) -> 1430000
D15: Остаточная стоимость ОС на начало периода | E15: тыс. руб. | H15: 0 | I15: =H19 -> 39000 | J15: =I19 -> 1080250 | K15: =J19 -> 1292875 | L15: =K19 -> 1267500 | M15: =L19 -> 1196000 | N15: =M19 -> 1124500 | O15: =N19 -> 1053000 | P15: =O19 -> 981500 | ... V15: =U19 -> 552500
D16: Ввод ОС за период | E16: тыс. руб. | H16: =H14 -> 40000 | I16: =I14-H14 -> 1070000 | J16: =J14-I14 -> 275000 | K16: =K14-J14 -> 45000 | L16: =L14-K14 -> 0 | M16: =M14-L14 -> 0 | N16: =N14-M14 -> 0 | O16: =O14-N14 -> 0 | P16: =P14-O14 -> 0 | ... V16: =V14-U14 -> 0
D17: Выбытие ОС за период | E17: тыс. руб. | H17: 0 | I17: 0 | J17: 0 | K17: 0 | L17: 0 | M17: 0 | N17: 0 | O17: 0 | P17: 0 | Q17: 0 | R17: 0 | S17: 0 | T17: 0 | U17: 0 | V17: 0
D18: Амортизация | E18: тыс. руб. | H18: =H16/CAPEX!$H$25/2 -> 1000 | I18: =H14/CAPEX!$H$25+I16/CAPEX!$H$25/2 -> 28750 | J18: =I14/CAPEX!$H$25+J16/CAPEX!$H$25/2 -> 62375 | K18: =J14/CAPEX!$H$25+K16/CAPEX!$H$25/2 -> 70375 | L18: =K14/CAPEX!$H$25+L16/CAPEX!$H$25/2 -> 71500 | M18: =L14/CAPEX!$H$25+M16/CAPEX!$H$25/2 -> 71500 | N18: =M14/CAPEX!$H$25+N16/CAPEX!$H$25/2 -> 71500 | O18: =N14/CAPEX!$H$25+O16/CAPEX!$H$25/2 -> 71500 | P18: =O14/CAPEX!$H$25+P16/CAPEX!$H$25/2 -> 71500 | ... V18: =U14/CAPEX!$H$25+V16/CAPEX!$H$25/2 -> 71500
D19: Остаточная стоимость ОС на конец периода | E19: тыс. руб. | H19: =H15+H16-H17-H18 -> 39000 | I19: =I15+I16-I17-I18 -> 1080250 | J19: =J15+J16-J17-J18 -> 1292875 | K19: =K15+K16-K17-K18 -> 1267500 | L19: =L15+L16-L17-L18 -> 1196000 | M19: =M15+M16-M17-M18 -> 1124500 | N19: =N15+N16-N17-N18 -> 1053000 | O19: =O15+O16-O17-O18 -> 981500 | ... V19: =V15+V16-V17-V18 -> 481000
D20: Среднегодовая стоимость ОС | E20: тыс. руб. | H20: =(H15+H19)/2 -> 19500 | I20: =(I15+I19)/2 -> 559625 | J20: =(J15+J19)/2 -> 1186562.5 | K20: =(K15+K19)/2 -> 1280187.5 | L20: =(L15+L19)/2 -> 1231750 | M20: =(M15+M19)/2 -> 1160250 | N20: =(N15+N19)/2 -> 1088750 | O20: =(O15+O19)/2 -> 1017250 | ... V20: =(V15+V19)/2 -> 516750
D21: Налог на имущество | E21: тыс. руб. | H21: =H20*'Исходные данные'!H20 -> 429 | I21: =I20*'Исходные данные'!I20 -> 12311.75 | J21: =J20*'Исходные данные'!J20 -> 26104.375 | K21: =K20*'Исходные данные'!K20 -> 28164.125 | L21: =L20*'Исходные данные'!L20 -> 27098.5 | M21: =M20*'Исходные данные'!M20 -> 25525.5 | N21: =N20*'Исходные данные'!N20 -> 23952.5 | O21: =O20*'Исходные данные'!O20 -> 22379.5 | ... V21: =V20*'Исходные данные'!V20 -> 11368.5
A23: 3 | B23: Налог на прибыль
D25: Прибыль/убыток периода | E25: тыс. руб. | H25: =SUM('Cash Flow'!H7:H9,'Cash Flow'!H18,'Cash Flow'!H25)-H18 -> -282544.86 | I25: =SUM('Cash Flow'!I7:I9,'Cash Flow'!I18,'Cash Flow'!I25)-I18 -> -493499.71 | J25: =SUM('Cash Flow'!J7:J9,'Cash Flow'!J18,'Cash Flow'!J25)-J18 -> 305650.13 | K25: =SUM('Cash Flow'!K7:K9,'Cash Flow'!K18,'Cash Flow'!K25)-K18 -> 1265047.2 | L25: =SUM('Cash Flow'!L7:L9,'Cash Flow'!L18,'Cash Flow'!L25)-L18 -> 1569002.4 | M25: =SUM('Cash Flow'!M7:M9,'Cash Flow'!M18,'Cash Flow'!M25)-M18 -> 2108541.4 | N25: =SUM('Cash Flow'!N7:N9,'Cash Flow'!N18,'Cash Flow'!N25)-N18 -> 1872541 | O25: =SUM('Cash Flow'!O7:O9,'Cash Flow'!O18,'Cash Flow'!O25)-O18 -> 1478158.3 | ... V25: =SUM('Cash Flow'!V7:V9,'Cash Flow'!V18,'Cash Flow'!V25)-V18 -> 1250682.8
D26: Прибыль/убыток нарастающим итогом | E26: тыс. руб. | H26: =H25 -> -282544.86 | I26: =H26+I25 -> -776044.57 | J26: =I26+J25 -> -470394.44 | K26: =J26+K25 -> 794652.71 | L26: =K26+L25 -> 2363655.1 | M26: =L26+M25 -> 4472196.5 | N26: =M26+N25 -> 6344737.5 | O26: =N26+O25 -> 7822895.8 | P26: =O26+P25 -> 9223435.9 | ... V26: =U26+V25 -> 17022528
D27: Налог на прибыль | E27: тыс. руб. | H27: =IF(H26<=0,0,IF(H25<=0,0,IF(G26>0,H25*'Исходные данные'!H22,Налоги!H26*'Исходные данные'!H22))) -> 0 | I27: =IF(I26<=0,0,IF(I25<=0,0,IF(H26>0,I25*'Исходные данные'!I22,Налоги!I26*'Исходные данные'!I22))) -> 0 | J27: =IF(J26<=0,0,IF(J25<=0,0,IF(I26>0,J25*'Исходные данные'!J22,Налоги!J26*'Исходные данные'!J22))) -> 0 | K27: =IF(K26<=0,0,IF(K25<=0,0,IF(J26>0,K25*'Исходные данные'!K22,Налоги!K26*'Исходные данные'!K22))) -> 158930.54 | L27: =IF(L26<=0,0,IF(L25<=0,0,IF(K26>0,L25*'Исходные данные'!L22,Налоги!L26*'Исходные данные'!L22))) -> 313800.48 | M27: =IF(M26<=0,0,IF(M25<=0,0,IF(L26>0,M25*'Исходные данные'!M22,Налоги!M26*'Исходные данные'!M22))) -> 421708.29 | N27: =IF(N26<=0,0,IF(N25<=0,0,IF(M26>0,N25*'Исходные данные'!N22,Налоги!N26*'Исходные данные'!N22))) -> 374508.2 | O27: =IF(O26<=0,0,IF(O25<=0,0,IF(N26>0,O25*'Исходные данные'!O22,Налоги!O26*'Исходные данные'!O22))) -> 295631.65 | ... V27: =IF(V26<=0,0,IF(V25<=0,0,IF(U26>0,V25*'Исходные данные'!V22,Налоги!V26*'Исходные данные'!V22))) -> 250136.57
D30: По расчету налога:
D31: Для начала проверяем, есть ли положительная прибыль накопленным итогом. Если нет,
D32: то налога на прибыль также нет. Если нарастающим итогом результат положительный,
D33: а в текущем периоде прибыли нет, то снова налога на прибыль нет. Далее, если и в текущем
D34: периоде прибыль есть и нарастающим итогом результат положительный, то надо понять, что
D35: меньше — прибыль текущего периода или прибыль нарастающим итогом (это зависит от того,
D36: был ли положительный результат нарастающим итогом в предыдущем периоде). На то, что
D37: меньше, и начисляем налог.

Sheet Cash Flow
B1: Параметры модели
D2: Номер периода | H2: =период -> 1 | I2: =период -> 2 | J2: =период -> 3 | K2: =период -> 4 | L2: =период -> 5 | M2: =период -> 6 | N2: =период -> 7 | O2: =период -> 8 | ... V2: =период -> 15
D3: Календарный год | H3: =период_знач -> 2020 | I3: =период_знач -> 2021 | J3: =период_знач -> 2022 | K3: =период_знач -> 2023 | L3: =период_знач -> 2024 | M3: =период_знач -> 2025 | N3: =период_знач -> 2026 | O3: =период_знач -> 2027 | ... V3: =период_знач -> 2034
A5: 1 | B5: Операционный денежный поток
D7: Доход предприятия | E7: тыс. руб. | H7: =Выручка!H19+Выручка!H20 -> 0 | I7: =Выручка!I19+Выручка!I20 -> 0 | J7: =Выручка!J19+Выручка!J20 -> 1215346.4 | K7: =Выручка!K19+Выручка!K20 -> 2344831.1 | L7: =Выручка!L19+Выручка!L20 -> 2516554.7 | M7: =Выручка!M19+Выручка!M20 -> 3025822.5 | N7: =Выручка!N19+Выручка!N20 -> 2771188.6 | O7: =Выручка!O19+Выручка!O20 -> 2346798.7 | ... V7: =Выручка!V19+Выручка!V20 -> 2091181
D8: Операционные затраты | E8: тыс. руб. | H8: =-OPEX!H42 -> -235500 | I8: =-OPEX!I42 -> -267600 | J8: =-OPEX!J42 -> -398482.43 | K8: =-OPEX!K42 -> -521863.82 | L8: =-OPEX!L42 -> -523065.88 | M8: =-OPEX!M42 -> -526630.76 | N8: =-OPEX!N42 -> -524848.32 | O8: =-OPEX!O42 -> -521877.59 | ... V8: =-OPEX!V42 -> -520088.27
D9: Налоги и отчисления в себестоимости | E9: тыс. руб. | H9: =-(OPEX!H44+OPEX!H45+Налоги!H8+Налоги!H10+Налоги!H21) -> -21929 | I9: =-(OPEX!I44+OPEX!I45+Налоги!I8+Налоги!I10+Налоги!I21) -> -33811.75 | J9: =-(OPEX!J44+OPEX!J45+Налоги!J8+Налоги!J10+Налоги!J21) -> -165810.44 | K9: =-(OPEX!K44+OPEX!K45+Налоги!K8+Налоги!K10+Налоги!K21) -> -280919.62 | L9: =-(OPEX!L44+OPEX!L45+Налоги!L8+Налоги!L10+Налоги!L21) -> -290167.25 | M9: =-(OPEX!M44+OPEX!M45+Налоги!M8+Налоги!M10+Налоги!M21) -> -319150.32 | N9: =-(OPEX!N44+OPEX!N45+Налоги!N8+Налоги!N10+Налоги!N21) -> -302299.28 | O9: =-(OPEX!O44+OPEX!O45+Налоги!O8+Налоги!O10+Налоги!O21) -> -275262.89 | ... V9: =-(OPEX!V44+OPEX!V45+Налоги!V8+Налоги!V10+Налоги!V21) -> -248909.91
D10: Налог на прибыль | E10: тыс. руб. | H10: =-Налоги!H27 -> 0 | I10: =-Налоги!I27 -> 0 | J10: =-Налоги!J27 -> 0 | K10: =-Налоги!K27 -> -158930.54 | L10: =-Налоги!L27 -> -313800.48 | M10: =-Налоги!M27 -> -421708.29 | N10: =-Налоги!N27 -> -374508.2 | O10: =-Налоги!O27 -> -295631.65 | ... V10: =-Налоги!V27 -> -250136.57
D11: Потребность в оборотных средствах | E11: тыс. руб. | H11: =-OPEX!H50 -> 0 | I11: =-OPEX!I50 -> 0 | J11: =-OPEX!J50 -> -154148.67 | K11: =-OPEX!K50 -> -51662.301 | L11: =-OPEX!L50 -> -432.74339 | M11: =-OPEX!M50 -> -1283.3549 | N11: =-OPEX!N50 -> 641.67746 | O11: =-OPEX!O50 -> 1069.4624 | ... V11: =-OPEX!V50 -> 205171.78
D13: Итого операционный денежный поток | E13: тыс. руб. | H13: =SUM(H7:H11) -> -257429 | I13: =SUM(I7:I11) -> -301411.75 | J13: =SUM(J7:J11) -> 496904.91 | K13: =SUM(K7:K11) -> 1331454.8 | L13: =SUM(L7:L11) -> 1389088.3 | M13: =SUM(M7:M11) -> 1757049.8 | N13: =SUM(N7:N11) -> 1570174.5 | O13: =SUM(O7:O11) -> 1255096.1 | ... V13: =SUM(V7:V11) -> 1277218
A15: 2 | B15: Инвестиционный денежный поток
D17: Вложения во внеоборотные активы | E17: тыс. руб. | H17: =-SUM(CAPEX!H12:H13,CAPEX!H16,CAPEX!H19:H20) -> -40000 | I17: =-SUM(CAPEX!I12:I13,CAPEX!I16,CAPEX!I19:I20) -> -1070000 | J17: =-SUM(CAPEX!J12:J13,CAPEX!J16,CAPEX!J19:J20) -> -275000 | K17: =-SUM(CAPEX!K12:K13,CAPEX!K16,CAPEX!K19:K20) -> -45000 | L17: =-SUM(CAPEX!L12:L13,CAPEX!L16,CAPEX!L19:L20) -> 0 | M17: =-SUM(CAPEX!M12:M13,CAPEX!M16,CAPEX!M19:M20) -> 0 | N17: =-SUM(CAPEX!N12:N13,CAPEX!N16,CAPEX!N19:N20) -> 0 | O17: =-SUM(CAPEX!O12:O13,CAPEX!O16,CAPEX!O19:O20) -> 0 | ... V17: =-SUM(CAPEX!V12:V13,CAPEX!V16,CAPEX!V19:V20) -> 0
D18: Выбытие ОС | E18: тыс. руб. | H18: 0 | I18: 0 | J18: 0 | K18: 0 | L18: 0 | M18: 0 | N18: 0 | O18: 0 | P18: 0 | Q18: 0 | R18: 0 | S18: 0 | T18: 0 | U18: 0 | V18: 0
D20: Итого инвестиционный денежный поток | E20: тыс. руб. | H20: =SUM(H17:H18) -> -40000 | I20: =SUM(I17:I18) -> -1070000 | J20: =SUM(J17:J18) -> -275000 | K20: =SUM(K17:K18) -> -45000 | L20: =SUM(L17:L18) -> 0 | M20: =SUM(M17:M18) -> 0 | N20: =SUM(N17:N18) -> 0 | O20: =SUM(O17:O18) -> 0 | ... V20: =SUM(V17:V18) -> 0
A22: 3 | B22: Финансовый денежный поток
D24: Поступление финансирования | E24: тыс. руб. | H24: =Финансирование!H16+Финансирование!H22 -> 321544.86 | I24: =Финансирование!I16+Финансирование!I22 -> 1534749.7 | J24: =Финансирование!J16+Финансирование!J22 -> 61123.539 | K24: =Финансирование!K16+Финансирование!K22 -> 0 | L24: =Финансирование!L16+Финансирование!L22 -> 0 | M24: =Финансирование!M16+Финансирование!M22 -> 0 | N24: =Финансирование!N16+Финансирование!N22 -> 0 | O24: =Финансирование!O16+Финансирование!O22 -> 0 | ... V24: =Финансирование!V16+Финансирование!V22 -> 0
D25: Выплата процентов по кредитам | E25: тыс. руб. | H25: =Финансирование!H25 -> -24115.865 | I25: =Финансирование!I25 -> -163337.96 | J25: =Финансирование!J25 -> -283028.45 | K25: =Финансирование!K25 -> -206625.52 | L25: =Финансирование!L25 -> -62819.16 | M25: =Финансирование!M25 -> 0 | N25: =Финансирование!N25 -> 0 | O25: =Финансирование!O25 -> 0 | ... V25: =Финансирование!V25 -> -3.7674909e-07
D26: Погашение тела кредитов и займов | E26: тыс. руб. | H26: =-Финансирование!H18-Финансирование!H24 -> 0 | I26: =-Финансирование!I18-Финансирование!I24 -> 0 | J26: =-Финансирование!J18-Финансирование!J24 -> 0 | K26: =-Финансирование!K18-Финансирование!K24 -> -1079829.3 | L26: =-Финансирование!L18-Финансирование!L24 -> -837588.8 | M26: =-Финансирование!M18-Финансирование!M24 -> 0 | N26: =-Финансирование!N18-Финансирование!N24 -> 0 | O26: =-Финансирование!O18-Финансирование!O24 -> 0 | ... V26: =-Финансирование!V18-Финансирование!V24 -> -5.0233211e-06
D28: Итого финансовый денежный поток | E28: тыс. руб. | H28: =SUM(H24:H26) -> 297429 | I28: =SUM(I24:I26) -> 1371411.8 | J28: =SUM(J24:J26) -> -221904.91 | K28: =SUM(K24:K26) -> -1286454.8 | L28: =SUM(L24:L26) -> -900407.96 | M28: =SUM(M24:M26) -> 0 | N28: =SUM(N24:N26) -> 0 | O28: =SUM(O24:O26) -> 0 | ... V28: =SUM(V24:V26) -> -5.4000702e-06
A30: 4 | B30: Итого денежный поток
D32: Итого денежный поток периода | E32: тыс. руб. | H32: =H13+H20+H28 -> 0 | I32: =I13+I20+I28 -> 0 | J32: =J13+J20+J28 -> 0 | K32: =K13+K20+K28 -> 0 | L32: =L13+L20+L28 -> 488680.36 | M32: =M13+M20+M28 -> 1757049.8 | N32: =N13+N20+N28 -> 1570174.5 | O32: =O13+O20+O28 -> 1255096.1 | ... V32: =V13+V20+V28 -> 1277218
D33: Итого денежный поток кумулятивный | E33: тыс. руб. | H33: =H32 -> 0 | I33: =H33+I32 -> 0 | J33: =I33+J32 -> 0 | K33: =J33+K32 -> 0 | L33: =K33+L32 -> 488680.36 | M33: =L33+M32 -> 2245730.1 | N33: =M33+N32 -> 3815904.6 | O33: =N33+O32 -> 5071000.7 | P33: =O33+P32 -> 6263146.7 | ... V33: =U33+V32 -> 13137023

Sheet Финансирование
B1: Параметры модели
D2: Номер периода | H2: =период -> 1 | I2: =период -> 2 | J2: =период -> 3 | K2: =период -> 4 | L2: =период -> 5 | M2: =период -> 6 | N2: =период -> 7 | O2: =период -> 8 | ... V2: =период -> 15
D3: Календарный год | H3: =период_календ -> 2020 | I3: =период_календ -> 2021 | J3: =период_календ -> 2022 | K3: =период_календ -> 2023 | L3: =период_календ -> 2024 | M3: =период_календ -> 2025 | N3: =период_календ -> 2026 | O3: =период_календ -> 2027 | ... V3: =период_календ -> #VALUE!
A5: 1 | B5: Справочно
D7: Стоимость привлечения финансирования | E7: % | H7: ='Исходные данные'!H74 -> 0.15 | I7: ='Исходные данные'!I74 -> 0.15 | J7: ='Исходные данные'!J74 -> 0.15 | K7: ='Исходные данные'!K74 -> 0.15 | L7: ='Исходные данные'!L74 -> 0.15 | M7: ='Исходные данные'!M74 -> 0.15 | N7: ='Исходные данные'!N74 -> 0.15 | O7: ='Исходные данные'!O74 -> 0.15 | ... V7: ='Исходные данные'!V74 -> 0.15
D8: Доля собственных средств в финансировании | E8: % | H8: ='Исходные данные'!H75 -> 0 | I8: ='Исходные данные'!I75 -> 0 | J8: ='Исходные данные'!J75 -> 0 | K8: ='Исходные данные'!K75 -> 0 | L8: ='Исходные данные'!L75 -> 0 | M8: ='Исходные данные'!M75 -> 0 | N8: ='Исходные данные'!N75 -> 0 | O8: ='Исходные данные'!O75 -> 0 | ... V8: ='Исходные данные'!V75 -> 0
D9: Операционный денежный поток | E9: тыс. руб. | H9: ='Cash Flow'!H13 -> -257429 | I9: ='Cash Flow'!I13 -> -301411.75 | J9: ='Cash Flow'!J13 -> 496904.91 | K9: ='Cash Flow'!K13 -> 1331454.8 | L9: ='Cash Flow'!L13 -> 1389088.3 | M9: ='Cash Flow'!M13 -> 1757049.8 | N9: ='Cash Flow'!N13 -> 1570174.5 | O9: ='Cash Flow'!O13 -> 1255096.1 | ... V9: ='Cash Flow'!V13 -> 1277218
D10: Инвестиционный денежный поток | E10: тыс. руб. | H10: ='Cash Flow'!H20 -> -40000 | I10: ='Cash Flow'!I20 -> -1070000 | J10: ='Cash Flow'!J20 -> -275000 | K10: ='Cash Flow'!K20 -> -45000 | L10: ='Cash Flow'!L20 -> 0 | M10: ='Cash Flow'!M20 -> 0 | N10: ='Cash Flow'!N20 -> 0 | O10: ='Cash Flow'!O20 -> 0 | ... V10: ='Cash Flow'!V20 -> 0
D11: Проценты к уплате | E11: тыс. руб. | H11: ='Cash Flow'!H25 -> -24115.865 | I11: ='Cash Flow'!I25 -> -163337.96 | J11: ='Cash Flow'!J25 -> -283028.45 | K11: ='Cash Flow'!K25 -> -206625.52 | L11: ='Cash Flow'!L25 -> -62819.16 | M11: ='Cash Flow'!M25 -> 0 | N11: ='Cash Flow'!N25 -> 0 | O11: ='Cash Flow'!O25 -> 0 | ... V11: ='Cash Flow'!V25 -> -3.7674909e-07
D12: Итого финансироуемый денежный поток | E12: тыс. руб. | H12: =SUM(H9:H11) -> -321544.86 | I12: =SUM(I9:I11) -> -1534749.7 | J12: =SUM(J9:J11) -> -61123.539 | K12: =SUM(K9:K11) -> 1079829.3 | L12: =SUM(L9:L11) -> 1326269.2 | M12: =SUM(M9:M11) -> 1757049.8 | N12: =SUM(N9:N11) -> 1570174.5 | O12: =SUM(O9:O11) -> 1255096.1 | ... V12: =SUM(V9:V11) -> 1277218
A14: 2 | B14: Финансирование за счет собственных средств
D16: Постуление финансирования | E16: тыс. руб. | H16: =IF(H12>0,0,-H12*H8) -> 0 | I16: =IF(I12>0,0,-I12*I8) -> 0 | J16: =IF(J12>0,0,-J12*J8) -> 0 | K16: =IF(K12>0,0,-K12*K8) -> 0 | L16: =IF(L12>0,0,-L12*L8) -> 0 | M16: =IF(M12>0,0,-M12*M8) -> 0 | N16: =IF(N12>0,0,-N12*N8) -> 0 | O16: =IF(O12>0,0,-O12*O8) -> 0 | ... V16: =IF(V12>0,0,-V12*V8) -> 0
D17: Остаток займов на конец периода | E17: тыс. руб. | H17: =H16-H18 -> 0 | I17: =H17+I16-I18 -> 0 | J17: =I17+J16-J18 -> 0 | K17: =J17+K16-K18 -> 0 | L17: =K17+L16-L18 -> 0 | M17: =L17+M16-M18 -> 0 | N17: =M17+N16-N18 -> 0 | O17: =N17+O16-O18 -> 0 | P17: =O17+P16-P18 -> 0 | ... V17: =U17+V16-V18 -> 0
D18: Возврат займов | E18: тыс. руб. | H18: =IF(H12<0,0,IF(G17=0,0,IF(G17>H12*H8,H12*H8,G17))) -> 0 | I18: =IF(I12<0,0,IF(H17=0,0,IF(H17>I12*I8,I12*I8,H17))) -> 0 | J18: =IF(J12<0,0,IF(I17=0,0,IF(I17>J12*J8,J12*J8,I17))) -> 0 | K18: =IF(K12<0,0,IF(J17=0,0,IF(J17>K12*K8,K12*K8,J17))) -> 0 | L18: =IF(L12<0,0,IF(K17=0,0,IF(K17>L12*L8,L12*L8,K17))) -> 0 | M18: =IF(M12<0,0,IF(L17=0,0,IF(L17>M12*M8,M12*M8,L17))) -> 0 | N18: =IF(N12<0,0,IF(M17=0,0,IF(M17>N12*N8,N12*N8,M17))) -> 0 | O18: =IF(O12<0,0,IF(N17=0,0,IF(N17>O12*O8,O12*O8,N17))) -> 0 | ... V18: =IF(V12<0,0,IF(U17=0,0,IF(U17>V12*V8,V12*V8,U17))) -> 0
A20: 3 | B20: Финансирование за счет кредита
D22: Постуление финансирования | E22: тыс. руб. | H22: =IF(H12>0,0,-H12*(1-H8)) -> 321544.86 | I22: =IF(I12>0,0,-I12*(1-I8)) -> 1534749.7 | J22: =IF(J12>0,0,-J12*(1-J8)) -> 61123.539 | K22: =IF(K12>0,0,-K12*(1-K8)) -> 0 | L22: =IF(L12>0,0,-L12*(1-L8)) -> 0 | M22: =IF(M12>0,0,-M12*(1-M8)) -> 0 | N22: =IF(N12>0,0,-N12*(1-N8)) -> 0 | O22: =IF(O12>0,0,-O12*(1-O8)) -> 0 | ... V22: =IF(V12>0,0,-V12*(1-V8)) -> 0
D23: Остаток кредитов на конец периода | E23: тыс. руб. | H23: =H22-H24 -> 321544.86 | I23: =H23+I22-I24 -> 1856294.6 | J23: =I23+J22-J24 -> 1917418.1 | K23: =J23+K22-K24 -> 837588.8 | L23: =K23+L22-L24 -> 0 | M23: =L23+M22-M24 -> 0 | N23: =M23+N22-N24 -> 0 | O23: =N23+O22-O24 -> 0 | P23: =O23+P22-P24 -> 0 | ... V23: =U23+V22-V24 -> -3.7746504e-06
D24: Возврат кредитов | E24: тыс. руб. | H24: =IF(H12<0,0,IF(G23=0,0,IF(G23>H12*(1-H8),H12*(1-H8),G23))) -> 0 | I24: =IF(I12<0,0,IF(H23=0,0,IF(H23>I12*(1-I8),I12*(1-I8),H23))) -> 0 | J24: =IF(J12<0,0,IF(I23=0,0,IF(I23>J12*(1-J8),J12*(1-J8),I23))) -> 0 | K24: =IF(K12<0,0,IF(J23=0,0,IF(J23>K12*(1-K8),K12*(1-K8),J23))) -> 1079829.3 | L24: =IF(L12<0,0,IF(K23=0,0,IF(K23>L12*(1-L8),L12*(1-L8),K23))) -> 837588.8 | M24: =IF(M12<0,0,IF(L23=0,0,IF(L23>M12*(1-M8),M12*(1-M8),L23))) -> 0 | N24: =IF(N12<0,0,IF(M23=0,0,IF(M23>N12*(1-N8),N12*(1-N8),M23))) -> 0 | O24: =IF(O12<0,0,IF(N23=0,0,IF(N23>O12*(1-O8),O12*(1-O8),N23))) -> 0 | ... V24: =IF(V12<0,0,IF(U23=0,0,IF(U23>V12*(1-V8),V12*(1-V8),U23))) -> 1.2486707e-06
D25: Проценты к уплате | E25: тыс. руб. | H25: =-G23*H7-H22*H7/2+H24*H7/2 -> -24115.865 | I25: =-H23*I7-I22*I7/2+I24*I7/2 -> -163337.96 | J25: =-I23*J7-J22*J7/2+J24*J7/2 -> -283028.45 | K25: =-J23*K7-K22*K7/2+K24*K7/2 -> -206625.52 | L25: =-K23*L7-L22*L7/2+L24*L7/2 -> -62819.16 | M25: =-L23*M7-M22*M7/2+M24*M7/2 -> 0 | N25: =-M23*N7-N22*N7/2+N24*N7/2 -> 0 | O25: =-N23*O7-O22*O7/2+O24*O7/2 -> 0 | ... V25: =-U23*V7-V22*V7/2+V24*V7/2 -> -9.3650306e-08
D29: По формуле возврат займов:
D31: Основная предпосылка — возвращаем кредиты и займы как можно скорее из потока — это эффективнее для акционеров и дешевле с точки зрения обслуживания кредитов. Сначала проверяем, положительный ли у нас в текущем периоде финансируемый денежный поток — если отрицательный, то возвращать нечем. Далее проверяем, есть ли еще остаток задолженности по займам — если остатка задолженности нет, то и возвращать нечего. Соответственно, если у нас и задолженность есть и денежный поток положительный, то мы что-то вернем акционерам. Что — зависит от размера потока. Проверяем, что меньше — остаток задолженности перед акционерами или весь поток, умноженный на долю акционерного капитала в финансировании. Что меньше — ту сумму и возвращаем (мы не можем вернуть весь долг, если денежный поток не позволяет это сделать и, в то же время, если поток позволяет вернуть весь остаток задолженности, то нет смысла ее оставлять и не возвращать).

Sheet Эфф-ть проекта
B1: Параметры модели
D2: Номер периода | H2: =период -> 1 | I2: =период -> 2 | J2: =период -> 3 | K2: =период -> 4 | L2: =период -> 5 | M2: =период -> 6 | N2: =период -> 7 | O2: =период -> 8 | ... V2: =период -> 15
D3: Календарный год | H3: =период_календ -> 2020 | I3: =период_календ -> 2021 | J3: =период_календ -> 2022 | K3: =период_календ -> 2023 | L3: =период_календ -> 2024 | M3: =период_календ -> 2025 | N3: =период_календ -> 2026 | O3: =период_календ -> 2027 | ... V3: =период_календ -> #VALUE!
A5: 1 | B5: Дисконтирование
D7: Ставка дисконтирования | E7: % | G7: ='Исходные данные'!H8 -> 0.15
D8: Коэффициент дисконтирования | E8: # | H8: =1/(1+$G$7)^(H2-0.5) -> 0.93250481 | I8: =1/(1+$G$7)^(I2-0.5) -> 0.81087375 | J8: =1/(1+$G$7)^(J2-0.5) -> 0.70510761 | K8: =1/(1+$G$7)^(K2-0.5) -> 0.61313705 | L8: =1/(1+$G$7)^(L2-0.5) -> 0.53316265 | M8: =1/(1+$G$7)^(M2-0.5) -> 0.4636197 | N8: =1/(1+$G$7)^(N2-0.5) -> 0.40314756 | O8: =1/(1+$G$7)^(O2-0.5) -> 0.3505631 | ... V8: =1/(1+$G$7)^(V2-0.5) -> 0.13178965
A10: 2 | B10: Показатели инвестиционной привлекательности
D12: Чистый денежный поток | E12: тыс. руб. | H12: ='Cash Flow'!H13+'Cash Flow'!H20+'Cash Flow'!H25 -> -321544.86 | I12: ='Cash Flow'!I13+'Cash Flow'!I20+'Cash Flow'!I25 -> -1534749.7 | J12: ='Cash Flow'!J13+'Cash Flow'!J20+'Cash Flow'!J25 -> -61123.539 | K12: ='Cash Flow'!K13+'Cash Flow'!K20+'Cash Flow'!K25 -> 1079829.3 | L12: ='Cash Flow'!L13+'Cash Flow'!L20+'Cash Flow'!L25 -> 1326269.2 | M12: ='Cash Flow'!M13+'Cash Flow'!M20+'Cash Flow'!M25 -> 1757049.8 | N12: ='Cash Flow'!N13+'Cash Flow'!N20+'Cash Flow'!N25 -> 1570174.5 | O12: ='Cash Flow'!O13+'Cash Flow'!O20+'Cash Flow'!O25 -> 1255096.1 | ... V12: ='Cash Flow'!V13+'Cash Flow'!V20+'Cash Flow'!V25 -> 1277218
D13: Чистый денежный поток накопленным итогом | E13: тыс. руб. | H13: =G13+H12 -> -321544.86 | I13: =H13+I12 -> -1856294.6 | J13: =I13+J12 -> -1917418.1 | K13: =J13+K12 -> -837588.8 | L13: =K13+L12 -> 488680.36 | M13: =L13+M12 -> 2245730.1 | N13: =M13+N12 -> 3815904.6 | O13: =N13+O12 -> 5071000.7 | ... V13: =U13+V12 -> 13137023
D14: Дисконтированный инвестиционный денежный поток | E14: тыс. руб. | H14: ='Cash Flow'!H20*H8 -> -37300.192 | I14: ='Cash Flow'!I20*I8 -> -867634.91 | J14: ='Cash Flow'!J20*J8 -> -193904.59 | K14: ='Cash Flow'!K20*K8 -> -27591.167 | L14: ='Cash Flow'!L20*L8 -> 0 | M14: ='Cash Flow'!M20*M8 -> 0 | N14: ='Cash Flow'!N20*N8 -> 0 | O14: ='Cash Flow'!O20*O8 -> 0 | ... V14: ='Cash Flow'!V20*V8 -> 0
D15: Чистый дисконтированный денежный поток | E15: тыс. руб. | H15: =H12*H8 -> -299842.13 | I15: =I12*I8 -> -1244488.2 | J15: =J12*J8 -> -43098.672 | K15: =K12*K8 -> 662083.35 | L15: =L12*L8 -> 707117.18 | M15: =M12*M8 -> 814602.89 | N15: =N12*N8 -> 633012.01 | O15: =O12*O8 -> 439990.36 | ... V15: =V12*V8 -> 168324.12
D16: Чистый дисконтированный денежный поток накопленным итогом | E16: тыс. руб. | H16: =G16+H15 -> -299842.13 | I16: =H16+I15 -> -1544330.4 | J16: =I16+J15 -> -1587429.1 | K16: =J16+K15 -> -925345.7 | L16: =K16+L15 -> -218228.51 | M16: =L16+M15 -> 596374.38 | N16: =M16+N15 -> 1229386.4 | O16: =N16+O15 -> 1669376.7 | ... V16: =U16+V15 -> 3353718.2
D17: NPV (чистая приведенная стоимость) | E17: тыс. руб. | H17: =SUM(H15:V15) -> 3353718.2
D18: IRR (внутренняя норма доходности) | E18: % | H18: =IFERROR(IRR(H12:V12),"∞") -> 0.44017655
D19: PI (индекс доходности инвестиций) | E19: # | H19: =H17/-SUM(H14:V14) -> 2.9772961
D20: PB (срок окупаемости) | E20: лет | H20: =IF(V13<0,"не окупается",COUNTIF(H13:V13,"<0")+IFERROR(ABS(OFFSET(H13,0,COUNTIF(H13:V13,"<0")-1)/OFFSET(H13,-1,COUNTIF(H13:V13,"<0"))),0)) -> 4.6315376
D21: DPB (дисконтированный срок окупаемости) | E21: лет | H21: =IF(H17<0,"∞",COUNTIF(H16:V16,"<0")+IFERROR(ABS(OFFSET(H16,0,COUNTIF(H16:V16,"<0")-1)/OFFSET(H16,-1,COUNTIF(H16:V16,"<0"))),0)) -> 5.2678956

Sheet Анализ чув-ти
B1: Параметры модели
D2: Номер периода | H2: =период -> 1 | I2: =период -> 2 | J2: =период -> 3 | K2: =период -> 4 | L2: =период -> 5 | M2: =период -> 6 | N2: =период -> 7 | O2: =период -> 8 | ... V2: =период -> 15
D3: Календарный год | H3: =период_календ -> 2020 | I3: =период_календ -> 2021 | J3: =период_календ -> 2022 | K3: =период_календ -> 2023 | L3: =период_календ -> 2024 | M3: =период_календ -> 2025 | N3: =период_календ -> 2026 | O3: =период_календ -> 2027 | ... V3: =период_календ -> #VALUE!
E5: Цена на золото
E6: -0.2 | F6: -0.15 | G6: -0.1 | H6: -0.05 | I6: 0 | J6: 0.05 | K6: 0.1 | L6: 0.15 | M6: 0.2
B7: Значение NPV | D7: ='Эфф-ть проекта'!H17 -> 3353718.2 | E7: 1776327.1 | F7: 2178447.9 | G7: 2580568.6 | H7: 2967252.5 | I7: 3353718.2 | J7: 3740183.8 | K7: 4126649.4 | L7: 4513115.1 | M7: 4899580.7
E9: Цены на ресурсы и материалы
E10: -0.2 | F10: -0.15 | G10: -0.1 | H10: -0.05 | I10: 0 | J10: 0.05 | K10: 0.1 | L10: 0.15 | M10: 0.2
B11: =B7 -> Значение NPV | C11: 0 | D11: ='Эфф-ть проекта'!H17 -> 3353718.2 | E11: 3570142 | F11: 3516036 | G11: 3461930.1 | H11: 3407824.1 | I11: 3353718.2 | J11: 3299612.2 | K11: 3245506.3 | L11: 3191400.3 | M11: 3137294.3

Sheet Лист1
H2: =период -> 1 | I2: =период -> 2 | J2: =период -> 3 | K2: =период -> 4 | L2: =период -> 5 | M2: =период -> 6 | N2: =период -> 7 | O2: =период -> 8 | ... V2: =период -> 15
